Workbook

Sheet process
A1: Process: | D1: Sophia | E1: BBI_ED | F1: 3 | G1: 4
A2: Setpoints | B2: Description | C2: Unit | D2: Value
A3: LWw | B3: Liquid weight setpoint | C3: kg | D3: 14 | E3: =VLOOKUP(A3,BBI_ED!$A$1:$C$205,2,FALSE) -> #N/A
A4: FHrelw | B4: Harvest rate | C4: % | D4: 20 | E4: =VLOOKUP(A4,BBI_ED!$A$1:$C$205,2,FALSE) -> #N/A
A5: NStw | B5: Setpoint for agitation speed | C5: 1/min | D5: 400 | E5: =VLOOKUP(A5,BBI_ED!$A$1:$C$205,2,FALSE) -> 0
A6: FnAIRw | B6: Aeration rate AIR extern | C6: l/min | D6: 7.5 | E6: =VLOOKUP(A6,BBI_ED!$A$1:$C$205,2,FALSE) -> 0
A7: FnN2w | B7: Aeration rate N2 extern | C7: l/min | D7: 0 | E7: =VLOOKUP(A7,BBI_ED!$A$1:$C$205,2,FALSE) -> 0
A8: FnO2w | B8: Aeration rate O2 extern | C8: l/min | D8: 0 | E8: =VLOOKUP(A8,BBI_ED!$A$1:$C$205,2,FALSE) -> 0
A9: FnCO2w | B9: Aeration rate CO2 extern | C9: l/min | D9: 0 | E9: =VLOOKUP(A9,BBI_ED!$A$1:$C$205,2,FALSE) -> 0
A10: FnGw | B10: Value of chosen aeration rate | C10: l/min | D10: 6 | E10: =VLOOKUP(A10,BBI_ED!$A$1:$C$205,2,FALSE) -> #N/A
A11: FRw | B11: Value of chosen constant feed rate | C11: l/h | D11: 0 | E11: =VLOOKUP(A11,BBI_ED!$A$1:$C$205,2,FALSE) -> #N/A
A12: pO2w | B12: Value of pO2 setpoint | C12: % | D12: 20 | E12: =VLOOKUP(A12,BBI_ED!$A$1:$C$205,2,FALSE) -> #N/A
A13: pHw | B13: Value of pH Setpoint | C13: - | D13: 6.7 | E13: =VLOOKUP(A13,BBI_ED!$A$1:$C$205,2,FALSE) -> #N/A
A14: thetaLw | B14: Value of temperature Setpoint | C14: °C | D14: 32 | E14: =VLOOKUP(A14,BBI_ED!$A$1:$C$205,2,FALSE) -> #N/A
A15: deltapGw | B15: Pressure setpoint | C15: bar | D15: 0.5 | E15: =VLOOKUP(A15,BBI_ED!$A$1:$C$205,2,FALSE) -> 0
A16: Initial values | E16: =VLOOKUP(A16,BBI_ED!$A$1:$C$205,2,FALSE) -> #N/A
A17: tmax | B17: Time limit for cultivation | C17: h | D17: 5 | E17: =VLOOKUP(A17,BBI_ED!$A$1:$C$205,2,FALSE) -> #N/A
A18: VL0 | B18: Initial volumme in reactor | C18: l | D18: 10 | E18: =VLOOKUP(A18,BBI_ED!$A$1:$C$205,2,FALSE) -> 5.5
A19: cS1L0 | B19: Initial glucose concentration t = 0 h | C19: g/l | D19: 5 | E19: =VLOOKUP(A19,BBI_ED!$A$1:$C$205,2,FALSE) -> #N/A
A20: cS2L0 | B20: Initial glycerine concentration t = 0 h | C20: g/l | D20: 0 | E20: =VLOOKUP(A20,BBI_ED!$A$1:$C$205,2,FALSE) -> #N/A
A21: cS3L0 | B21: Initial acetate concentration t = 0 h | C21: g/l | D21: 0 | E21: =VLOOKUP(A21,BBI_ED!$A$1:$C$205,2,FALSE) -> #N/A
A22: cXL0 | B22: Initial cell concentration t = 0 h | C22: g/l | D22: 3 | E22: =VLOOKUP(A22,BBI_ED!$A$1:$C$205,2,FALSE) -> 50
A23: Aeration parameters | E23: =VLOOKUP(A23,BBI_ED!$A$1:$C$205,2,FALSE) -> #N/A
A24: pGcal | B24: Pressure at calibration | C24: n/m^2 | D24: 150000 | E24: =VLOOKUP(A24,BBI_ED!$A$1:$C$205,2,FALSE) -> 0
A25: xOGcal | B25: Molar concentration of oxygen at calibration | C25: - | D25: 0.2094 | E25: =VLOOKUP(A25,BBI_ED!$A$1:$C$205,2,FALSE) -> 0
A26: xCGin | B26: Molar concentration of carbon dioxide in aeration | C26: - | D26: 0.004 | E26: =VLOOKUP(A26,BBI_ED!$A$1:$C$205,2,FALSE) -> #N/A
A27: cS1R | B27: Glucose concentration in reservoir | C27: g/l | D27: 200 | E27: =VLOOKUP(A27,BBI_ED!$A$1:$C$205,2,FALSE) -> 0
A28: cOR | B28: Dissolved oxygen concentration in reservoir | C28: g/l | D28: 0 | E28: =VLOOKUP(A28,BBI_ED!$A$1:$C$205,2,FALSE) -> 0
A29: CCRtot | B29: Total CO2 concentration in reservoir | C29: mol/l | D29: 0 | E29: =VLOOKUP(A29,BBI_ED!$A$1:$C$205,2,FALSE) -> 0
A30: VR0 | B30: Maximum volume of feed reservoir at t = 0 h | C30: l | D30: 2 | E30: =VLOOKUP(A30,BBI_ED!$A$1:$C$205,2,FALSE) -> 5
A31: cS2R | B31: Concentration of glycerine in glucose reservoir | C31: g/l | D31: 0 | E31: =VLOOKUP(A31,BBI_ED!$A$1:$C$205,2,FALSE) -> 0
A32: cXR | B32: Concentration of cells in glucose reservoir | C32: g/l | D32: 0 | E32: =VLOOKUP(A32,BBI_ED!$A$1:$C$205,2,FALSE) -> 0
A33: CPRtot | B33: Concentration of product in glucose reservoir | C33: g/l | D33: 0 | E33: =VLOOKUP(A33,BBI_ED!$A$1:$C$205,2,FALSE) -> 0
A34: CAlT2tot | B34: pH-base reservoir concentration (ammonia) | C34: mol/l | D34: 16.47 | E34: =VLOOKUP(A34,BBI_ED!$A$1:$C$205,2,FALSE) -> 16.47
A35: CCT1tot | B35: Total CO2 concentration in acid reservoir | C35: mol/l | D35: 0 | E35: =VLOOKUP(A35,BBI_ED!$A$1:$C$205,2,FALSE) -> 0
... A43: kLamax | B43: Maximum value of kLa | C43: l/min | D43: 1469 | E43: =VLOOKUP(A43,BBI_ED!$A$1:$C$205,2,FALSE) -> 1469
A44: temperature | E44: =VLOOKUP(A44,BBI_ED!$A$1:$C$205,2,FALSE) -> #N/A
A45: thetaL0 | B45: Initial temperature in liquid phase at t = 0 h | C45: °C | D45: 32 | E45: =VLOOKUP(A45,BBI_ED!$A$1:$C$205,2,FALSE) -> #N/A
A46: thetaD0 | B46: Initial temperature in double jacket at t = 0 h | C46: °C | D46: 32 | E46: =VLOOKUP(A46,BBI_ED!$A$1:$C$205,2,FALSE) -> #N/A
A47: medium | E47: =VLOOKUP(A47,BBI_ED!$A$1:$C$205,2,FALSE) -> #N/A
...

Sheet general
A1: Variable | B1: Description | C1: Unit | D1: Value
A2: xOAIR | B2: Molar concentration of oxygen in AIR | C2: - | D2: 0.2094 | E2: =VLOOKUP(A2,BBI_ED!$A$1:$C$205,2,FALSE) -> 0.2094 | H2: xOAIR | I2: x_{OAIR}
A3: xCAIR | B3: Molar concentration of carbondioxide in AIR | C3: - | D3: 0.0003 | E3: =VLOOKUP(A3,BBI_ED!$A$1:$C$205,2,FALSE) -> 0.0003 | H3: xCAIR | I3: x_{CAIR}
A4: HnO2 | B4: O2 Henry constant under normal conditions | C4: N*m/kg | D4: 1448000 | E4: =VLOOKUP(A4,BBI_ED!$A$1:$C$205,2,FALSE) -> 1448000 | H4: HnO2 | I4: H_{nO2}
A5: HO20 | B5: O2 Henry constant | C5: N*m/kg | D5: 1440000 | E5: =VLOOKUP(A5,BBI_ED!$A$1:$C$205,2,FALSE) -> #N/A | H5: HO20 | I5: H_{O20}
A6: HnCO2 | B6: CO2 Henry constant under normal conditions | C6: N*m/kg | D6: 30010 | E6: =VLOOKUP(A6,BBI_ED!$A$1:$C$205,2,FALSE) -> 30010 | H6: HnCO2 | I6: H_{nCO2}
A7: HCO20 | B7: CO2 Henry constant | C7: N*m/kg | D7: 30010 | E7: =VLOOKUP(A7,BBI_ED!$A$1:$C$205,2,FALSE) -> #N/A | H7: HCO20 | I7: H_{CO20}
A8: VnM | B8: Gas volume under normal conditions | C8: l/mol | D8: 22.412 | E8: =VLOOKUP(A8,BBI_ED!$A$1:$C$205,2,FALSE) -> 22.412 | H8: VnM | I8: V_{nM}
A9: MO2 | B9: Molar mass of O2 | C9: g/mol | D9: 32 | E9: =VLOOKUP(A9,BBI_ED!$A$1:$C$205,2,FALSE) -> 32 | H9: MO2 | I9: M_{O2}
A10: MCO2 | B10: Molar mass of CO2 | C10: g/mol | D10: 44 | E10: =VLOOKUP(A10,BBI_ED!$A$1:$C$205,2,FALSE) -> 44 | H10: MCO2 | I10: M_{CO2}
A11: TnG | B11: Gas temperature under normal conditions | C11: K | D11: 273.15 | E11: =VLOOKUP(A11,BBI_ED!$A$1:$C$205,2,FALSE) -> 273.15 | H11: TnG | I11: T_{nG}
A12: pnG | B12: Gas pressure under normal conditions | C12: N/m^2 | D12: 101330 | E12: =VLOOKUP(A12,BBI_ED!$A$1:$C$205,2,FALSE) -> 101300 | H12: pnG | I12: p_{nG}
A13: R | B13: Gas constant | C13: N*m/(kmol*K) | D13: 8314 | E13: =VLOOKUP(A13,BBI_ED!$A$1:$C$205,2,FALSE) -> 8314 | H13: R | I13: R
... A31: alpha | B31: Parameter for kLa calculation | C31: - | D31: 0.5 | E31: =VLOOKUP(A31,BBI_ED!$A$1:$C$205,2,FALSE) -> 0.5 | H31: alpha | I31: \alpha_{}
A32: beta | B32: Parameter for kLa calculation | C32: - | D32: 0.5 | E32: =VLOOKUP(A32,BBI_ED!$A$1:$C$205,2,FALSE) -> 0.5 | H32: beta
A33: gamma | B33: Parameter for kLa calculation | C33: - | D33: -0.05 | E33: =VLOOKUP(A33,BBI_ED!$A$1:$C$205,2,FALSE) -> -0.05 | H33: gamma | I33: \gamma_{}

Sheet bioreactors
A1: Bioreactor | D1: ED | E1: BBI_ED
A2: Reactorvolume | D2: 5.5
A3: Instrumentation | B3: Description | C3: Unit | D3: Value
A4: FRmax | B4: Maximum feed pump rate | C4: l/h | D4: 0.5 | E4: =VLOOKUP(A4,BBI_ED!$A$1:$C$205,2,FALSE) -> 0 | K4: FRmax | L4: F_{Rmax}
A5: FnAIRmax | B5: Maximumm possible air aeration rate | C5: l/min | D5: 20 | E5: =VLOOKUP(A5,BBI_ED!$A$1:$C$205,2,FALSE) -> 10 | K5: FnAIRmax | L5: F_{AIRmax}
A6: FnO2max | B6: Maximum possible O2 aeration rate | C6: l/min | D6: 5 | E6: =VLOOKUP(A6,BBI_ED!$A$1:$C$205,2,FALSE) -> 5 | K6: FnO2max | L6: F_{O2max}
A7: FnN2max | B7: Maximum possible N2 aeration rate | C7: l/min | D7: 5 | E7: =VLOOKUP(A7,BBI_ED!$A$1:$C$205,2,FALSE) -> 5 | K7: FnN2max | L7: F_{N2max}
A8: FnCO2max | B8: Maximum possible CO2 aeration rate | C8: l/min | D8: 2 | E8: =VLOOKUP(A8,BBI_ED!$A$1:$C$205,2,FALSE) -> 2 | K8: FnCO2max | L8: F_{CO2max}
A9: FnGmax | B9: Summed up maximum aeration rate | C9: l/min | D9: 27 | E9: =VLOOKUP(A9,BBI_ED!$A$1:$C$205,2,FALSE) -> 17 | K9: FnGmax | L9: F_{Gmax}
A10: NStmax | B10: Maximum possible stirrer speed | C10: 1/min | D10: 1500 | E10: =VLOOKUP(A10,BBI_ED!$A$1:$C$205,2,FALSE) -> 1500 | K10: NStmax | L10: N_{Stmax}
A11: TMpO2 | B11: Time constant pO2 measurement system 0.0025 h = 9 s | C11: h | D11: 0.0025 | E11: =VLOOKUP(A11,BBI_ED!$A$1:$C$205,2,FALSE) -> 0.0025 | K11: TMpO2 | L11: TM_{pO2}
A12: TMxO2 | B12: Time constant xO2 measurement system 0.0042 h = 15 s*/ | C12: h | D12: 0.0042 | E12: =VLOOKUP(A12,BBI_ED!$A$1:$C$205,2,FALSE) -> 0.0042 | K12: TMxO2 | L12: TM_{xO2}
A13: TMxCO2 | B13: Time constant xCO2 measurement system | C13: h | D13: 0.0042 | E13: =VLOOKUP(A13,BBI_ED!$A$1:$C$205,2,FALSE) -> 0.0042 | K13: TMxCO2 | L13: TM_{xCO2}
A14: TMpH | B14: Time constant pH measurement system | C14: h | D14: 0.0042 | E14: =VLOOKUP(A14,BBI_ED!$A$1:$C$205,2,FALSE) -> 0.0042 | K14: TMpH | L14: TM_{pH}
A15: FHmax | B15: Maximum harvest pump rate | C15: l/h | D15: 5 | E15: =VLOOKUP(A15,BBI_ED!$A$1:$C$205,2,FALSE) -> 5 | K15: FHmax | L15: F_{Hmax}
... A18: FT2max | B18: Maximum titration rate of the alkali pump | C18: 1/h | D18: 0.5 | E18: =VLOOKUP(A18,BBI_ED!$A$1:$C$205,2,FALSE) -> 1 | K18: FT2max | L18: F_{T2max}
A19: Temperature
A20: alphaH | B20: Heat transfer coefficient of the heating medium | C20: W/(m^2*K) | D20: 5000 | E20: =VLOOKUP(A20,BBI_ED!$A$1:$C$205,2,FALSE) -> 5000 | K20: alphaH | L20: \alpha_{H}
A21: alphaTh | B21: Heat transfer coefficient of the temperature medium | C21: W/(m^2*K) | D21: 1000 | E21: =VLOOKUP(A21,BBI_ED!$A$1:$C$205,2,FALSE) -> 1000 | K21: alphaTh | L21: \alpha_{Th}
A22: deltaHTh | B22: Wall diameter between H and Th | C22: m | D22: 0.001 | E22: =VLOOKUP(A22,BBI_ED!$A$1:$C$205,2,FALSE) -> 0.001 | K22: deltaHTh | L22: \delta_{HTh}
A23: lamdaHTh | B23: Thermal conductivity of the wall between H and Th | C23: W/(m*K) | D23: 380 | E23: =VLOOKUP(A23,BBI_ED!$A$1:$C$205,2,FALSE) -> 380 | K23: lamdaHTh | L23: \lamda_{HTh}
A24: mdotCmax | B24: Maximum cooling-water mass flux 8 | C24: kg/h | D24: 1500 | E24: =VLOOKUP(A24,BBI_ED!$A$1:$C$205,2,FALSE) -> 150 | K24: mdotCmax | L24: \dot m_{Cmax}
A25: thetaCin | B25: Temperature cooling-water inlet | C25: °C | D25: 15 | E25: =VLOOKUP(A25,BBI_ED!$A$1:$C$205,2,FALSE) -> 15 | K25: thetaCin | L25: \theta_{Cin}
A26: mC | B26: Mass of the cooling system | C26: kg | D26: 1 | E26: =VLOOKUP(A26,BBI_ED!$A$1:$C$205,2,FALSE) -> 1 | K26: mC | L26: m_{C}
A27: alphaC | B27: Heat transfer coefficient of cooling-water | C27: W/(m^2K) | D27: 3700 | E27: =VLOOKUP(A27,BBI_ED!$A$1:$C$205,2,FALSE) -> 3700 | K27: alphaC | L27: \alpha_{C}
A28: deltaCT | B28: Exchanging diameter of the heat exchanger | C28: m | D28: 0.003 | E28: =VLOOKUP(A28,BBI_ED!$A$1:$C$205,2,FALSE) -> 0.003 | K28: deltaCT | L28: \Delta_{CT}
A29: lamdaCT | B29: Thermal conductivity of the exchange wall | C29: W/(mK) | D29: 46 | E29: =VLOOKUP(A29,BBI_ED!$A$1:$C$205,2,FALSE) -> 46 | K29: lamdaCT | L29: \lamda_{CT}
A30: ACT | B30: Surface of the heat exchanger | C30: m^2 | D30: 0.5 | E30: =VLOOKUP(A30,BBI_ED!$A$1:$C$205,2,FALSE) -> 0.5 | K30: ACT | L30: A_{CT}
A31: VH | B31: Volume of heating system | C31: m^3 | D31: 0.0003 | E31: =VLOOKUP(A31,BBI_ED!$A$1:$C$205,2,FALSE) -> 0.0003 | K31: VH | L31: V_{H}
... A59: alphaU | B59: Heat transfer coefficient environment - wall | C59: W/(m^2 K) | D59: 10 | E59: =VLOOKUP(A59,BBI_ED!$A$1:$C$205,2,FALSE) -> 10 | K59: alphaU | L59: \alpha_{U}

Sheet organisms
A1: Organism
A2: growth
A3: my1opt | B3: Maximum specific growth rate glucose | C3: 1/h | D3: 0.46 | E3: =VLOOKUP(A3,BBI_ED!$A$1:$C$205,2,FALSE) -> 0.46 | H3: my1opt | I3: μ_{1opt}
A4: my2opt | B4: Maximum specific growth rate glycerol | C4: 1/h | D4: 0.35 | E4: =VLOOKUP(A4,BBI_ED!$A$1:$C$205,2,FALSE) -> 0.35 | H4: my2opt | I4: μ_{2opt}
A5: my3opt | B5: Maximum specific growth rate acetate | C5: 1/h | D5: 0.1 | E5: =VLOOKUP(A5,BBI_ED!$A$1:$C$205,2,FALSE) -> 0.1 | H5: my3opt | I5: μ_{3opt}
A6: qOpXm | B6: Specific O2 maintenance rate | C6: 1/h | D6: 0.005 | E6: =VLOOKUP(A6,BBI_ED!$A$1:$C$205,2,FALSE) -> 0.0193 | H6: qOpXm | I6: q_{O/Xm}
A7: qS1pXm | B7: Spcific substrate maintenance rate glucose | C7: 1/h | D7: 0.06 | E7: =VLOOKUP(A7,BBI_ED!$A$1:$C$205,2,FALSE) -> 0.0611 | H7: qS1pXm | I7: q_{S1/Xm}
A8: kS1 | B8: Substrate limitation constant glucose | C8: g/l | D8: 0.04 | E8: =VLOOKUP(A8,BBI_ED!$A$1:$C$205,2,FALSE) -> 0.04 | H8: kS1 | I8: k_{S1}
A9: kS2 | B9: Substrate limitation constant glycerol | C9: g/l | D9: 0.05 | E9: =VLOOKUP(A9,BBI_ED!$A$1:$C$205,2,FALSE) -> 0.05 | H9: kS2 | I9: k_{S2}
A10: kS3 | B10: Substrate limitation constant acetate | C10: g/l | D10: 0.06 | E10: =VLOOKUP(A10,BBI_ED!$A$1:$C$205,2,FALSE) -> 0.06 | H10: kS3 | I10: k_{S3}
A11: kI21 | B11: Inhibition of glycerine uptake in presence of glucose | C11: g/l | D11: 0.0018 | E11: =VLOOKUP(A11,BBI_ED!$A$1:$C$205,2,FALSE) -> 0.0018 | H11: kI21 | I11: k_{I21}
A12: kI31 | B12: Inhibition of acetate uptake in presence of glucose | C12: g/l | D12: 0.0018 | E12: =VLOOKUP(A12,BBI_ED!$A$1:$C$205,2,FALSE) -> 0.0018 | H12: kI31 | I12: k_{I31}
A13: kI32 | B13: Inhibition of acetate uptake due to glycerine | C13: g/l | D13: 0.003 | E13: =VLOOKUP(A13,BBI_ED!$A$1:$C$205,2,FALSE) -> 0.003 | H13: kI32 | I13: k_{I32}
A14: kIPO | B14: Inhibition of acetate production due to O2 | C14: g/l | D14: 0.0005 | E14: =VLOOKUP(A14,BBI_ED!$A$1:$C$205,2,FALSE) -> 0.0005 | H14: kIPO | I14: k_{IPO}
... A28: yXpO | B28: Yield coefficient of gram cells per gram oxygen | C28: - | D28: 0.40601 | E28: =VLOOKUP(A28,BBI_ED!$A$1:$C$205,2,FALSE) -> #N/A | H28: yXpO | I28: y_{X/O}
A29: Temperature
A30: thetaLmingr | B30: Minimum liquid temperature required for growth | C30: °C | D30: 5 | E30: =VLOOKUP(A30,BBI_ED!$A$1:$C$205,2,FALSE) -> 5 | H30: thetaLmingr | I30: \theta_{Lmingr}
A31: thetaLmaxgr | B31: Maximum liquid temperature required for growth | C31: °C | D31: 47 | E31: =VLOOKUP(A31,BBI_ED!$A$1:$C$205,2,FALSE) -> 47 | H31: thetaLmaxgr | I31: \theta_{Lmaxgr}
A32: thetaLoptgr | B32: Optimal temperature required for growth | C32: °C | D32: 35 | E32: =VLOOKUP(A32,BBI_ED!$A$1:$C$205,2,FALSE) -> 35 | H32: thetaLoptgr | I32: \theta_{Loptgr}
A33: thetaDJ_WP | B33: Added by me, working point of cascade temperature slave controller | C33: °C | D33: 32 | E33: =VLOOKUP(A33,BBI_ED!$A$1:$C$205,2,FALSE) -> #N/A | H33: thetaDJ_WP | I33: \theta_{DJ_WP}
A34: foam
A35: qhpX | B35: Cellspecific foam build up rate | C35: l/(g*h) | D35: 0.1 | E35: =VLOOKUP(A35,BBI_ED!$A$1:$C$205,2,FALSE) -> 0.1 | H35: qhpX | I35: q_{h/X}
A36: tauF0 | B36: Time constant of foam formation at cXL = 0 g/l | C36: h | D36: 0.0125 | E36: =VLOOKUP(A36,BBI_ED!$A$1:$C$205,2,FALSE) -> 0.0125 | H36: tauF0 | I36: \tau_{F0}
A37: KFpX | B37: Foam consistency factor | C37: l/g | D37: 0.09 | E37: =VLOOKUP(A37,BBI_ED!$A$1:$C$205,2,FALSE) -> 0.09 | H37: KFpX | I37: K_{F/X}
A38: KAF | B38: Cell antifoam adsorption constant | C38: (g*h)/l | D38: 4 | E38: =VLOOKUP(A38,BBI_ED!$A$1:$C$205,2,FALSE) -> 4 | H38: KAF | I38: K_{AF}
A39: VAF | B39: Activity decline due to antifoam addition | C39: - | D39: 0.975 | E39: =VLOOKUP(A39,BBI_ED!$A$1:$C$205,2,FALSE) -> 0.975 | H39: VAF | I39: V_{AF}
A40: AAFtast | B40: Antifoam-activity gain per addition step Ttast | C40: 1/h | D40: 100 | E40: =VLOOKUP(A40,BBI_ED!$A$1:$C$205,2,FALSE) -> 100 | H40: AAFtast | I40: A_{AFtast}
A41: Ttast | B41: Addition unit Ttast | C41: h | D41: 8.333e-05 | E41: =VLOOKUP(A41,BBI_ED!$A$1:$C$205,2,FALSE) -> 8.333e-05 | H41: Ttast | I41: T_{tast}
A42: pH
A43: pHLmingr | B43: Minimum pH required for growth | C43: - | D43: 4 | E43: =VLOOKUP(A43,BBI_ED!$A$1:$C$205,2,FALSE) -> 4 | H43: pHLmingr | I43: 0
A44: pHLmaxgr | B44: Maximum pH required for growth | C44: - | D44: 9 | E44: =VLOOKUP(A44,BBI_ED!$A$1:$C$205,2,FALSE) -> 9 | H44: pHLmaxgr | I44: pH_{Lmaxgr}
A45: pHLoptgr | B45: Optimal pH required for growth | C45: - | D45: 6.8 | E45: =VLOOKUP(A45,BBI_ED!$A$1:$C$205,2,FALSE) -> 6.8 | H45: pHLoptgr | I45: pH_{Loptgr}

Sheet BBI_ED
A1: AAF | B1: 0 | C1: -
A2: AAFtast | B2: 100 | C2: 1/h
A3: ACT | B3: 0.5 | C3: m^2
A4: ADL | B4: 1.13 | C4: m^2
A5: ADU | B5: 1.4 | C5: m^2
A6: AHTh | B6: 0.13 | C6: m^2
A7: alpha | B7: 0.5 | C7: -
A8: alphaC | B8: 3700 | C8: W/(m^2K)
A9: alphaD | B9: 2000 | C9: W/(m^2K)
A10: alphaH | B10: 5000 | C10: W/(m^2*K)
A11: alphaL | B11: 4000 | C11: W/(m^2K)
A12: alphaT | B12: 3700 | C12: W/(m^2K)
... A137: NStw | B137: 0 | C137: 1/min
A138: Parameter:
A139: pGcal | B139: 0 | C139: N/m^2
A140: pH | B140: 7.5 | C140: -
A141: pH0 | B141: 7.5 | C141: -
A142: phiTcC | B142: 2.1208 | C142: -
A143: pHLmaxgr | B143: 9 | C143: -
A144: pHLmingr | B144: 4 | C144: -
A145: pHLoptgr | B145: 6.8 | C145: -
A146: PHmax | B146: 2000 | C146: W
A147: pnG | B147: 101300 | C147: N/m^2
A148: pO2 | B148: 100 | C148: %
A149: qhpX | B149: 0.1 | C149: l/(gh)
A150: Qny | B150: 649.83 | C150: kJ
... A205: yXpS3gr | B205: 0.2 | C205: -

Sheet Model Properties
A1: propertyTab | F1: Bacillus academii
A2: propertyID | B2: category | C2: name | D2: tex | E2: unit | F2: tex_unit | G2: type | H2: internal_order | I2: external_order | J2: organismID2 | K2: propertyID2 | L2: value2 | M2: description2 | N2: Comments | O2: organismID1 | P2: propertyID1 | Q2: value1 | R2: description1 | S2: Categories | T2: Column1 | U2: min_limit | V2: max_limit | W2: min_limit2 | X2: max_limit2
A3: 1 | B3: 1 | C3: NStw | D3: N_{Stw} | E3: 1/min | F3: min^{-1} | G3: editfield | H3: 1 | I3: =TEXT(Tabelle2[[#This Row],[category]],"00")&TEXT(Tabelle2[[#This Row],[internal_order]],"00") -> 0101 | J3: 2 | K3: =Tabelle2[[#This Row],[propertyID]] -> 1 | L3: 400 | M3: Setpoint for agitation speed | O3: 1 | P3: =Tabelle2[[#This Row],[propertyID]] -> 1 | Q3: 400 | R3: Setpoint for agitation speed | S3: Setpoint | U3: 0 | W3: 0
A4: 2 | B4: 1 | C4: pHw | D4: pH_{w} | E4: - | F4: - | G4: editfield | H4: 2 | I4: =TEXT(Tabelle2[[#This Row],[category]],"00")&TEXT(Tabelle2[[#This Row],[internal_order]],"00") -> 0102 | J4: 2 | K4: =Tabelle2[[#This Row],[propertyID]] -> 2 | L4: 4.8 | M4: Value of pH Setpoint | N4: Yuma | O4: 1 | P4: =Tabelle2[[#This Row],[propertyID]] -> 2 | Q4: 6.7 | R4: Value of pH Setpoint | S4: Setpoint | U4: 0 | W4: 0 | X4: 14
A5: 3 | B5: 1 | C5: pO2w | D5: pO_{2w} | E5: % | F5: % | G5: editfield | H5: 3 | I5: =TEXT(Tabelle2[[#This Row],[category]],"00")&TEXT(Tabelle2[[#This Row],[internal_order]],"00") -> 0103 | J5: 2 | K5: =Tabelle2[[#This Row],[propertyID]] -> 3 | L5: 20 | M5: Value of pO2 setpoint | O5: 1 | P5: =Tabelle2[[#This Row],[propertyID]] -> 3 | Q5: 20 | R5: Value of pO2 setpoint | S5: Setpoint | U5: 0 | W5: 0
A6: 4 | B6: 1 | C6: thetaLw | D6: \vartheta_{Lw} | E6: °C | F6: °C | G6: editfield | H6: 4 | I6: =TEXT(Tabelle2[[#This Row],[category]],"00")&TEXT(Tabelle2[[#This Row],[internal_order]],"00") -> 0104 | J6: 2 | K6: =Tabelle2[[#This Row],[propertyID]] -> 4 | L6: 30 | M6: Value of temperature Setpoint | O6: 1 | P6: =Tabelle2[[#This Row],[propertyID]] -> 4 | Q6: 32 | R6: Value of temperature Setpoint | S6: Setpoint | U6: 12 | W6: 0
A7: 5 | B7: 1 | C7: LWw | D7: L_{Ww} | E7: kg | F7: kg | G7: editfield | H7: 5 | I7: =TEXT(Tabelle2[[#This Row],[category]],"00")&TEXT(Tabelle2[[#This Row],[internal_order]],"00") -> 0105 | J7: 2 | K7: =Tabelle2[[#This Row],[propertyID]] -> 5 | L7: 14 | M7: Liquid weight setpoint | O7: 1 | P7: =Tabelle2[[#This Row],[propertyID]] -> 5 | Q7: 14 | R7: Liquid weight setpoint | S7: Setpoint | U7: 0 | W7: 0
A8: 6 | B8: 1 | C8: FnGw | D8: F_{nGw} | E8: l/min | F8: lmin^{-1} | G8: editfield | H8: 6 | I8: =TEXT(Tabelle2[[#This Row],[category]],"00")&TEXT(Tabelle2[[#This Row],[internal_order]],"00") -> 0106 | J8: 2 | K8: =Tabelle2[[#This Row],[propertyID]] -> 6 | L8: 6 | M8: Value of chosen aeration rate | O8: 1 | P8: =Tabelle2[[#This Row],[propertyID]] -> 6 | Q8: 6 | R8: Value of chosen aeration rate | S8: Setpoint | U8: 0 | W8: 0
A9: 7 | B9: 1 | C9: FnAIRw | D9: F_{nAIRw} | E9: l/min | F9: lmin^{-1} | G9: editfield | H9: 7 | I9: =TEXT(Tabelle2[[#This Row],[category]],"00")&TEXT(Tabelle2[[#This Row],[internal_order]],"00") -> 0107 | J9: 2 | K9: =Tabelle2[[#This Row],[propertyID]] -> 7 | L9: 7.5 | M9: Aeration rate AIR extern | O9: 1 | P9: =Tabelle2[[#This Row],[propertyID]] -> 7 | Q9: 7.5 | R9: Aeration rate AIR extern | S9: Setpoint | U9: 0 | W9: 0
A10: 8 | B10: 1 | C10: FnO2w | D10: F_{nO2w} | E10: l/min | F10: lmin^{-1} | G10: editfield | H10: 8 | I10: =TEXT(Tabelle2[[#This Row],[category]],"00")&TEXT(Tabelle2[[#This Row],[internal_order]],"00") -> 0108 | J10: 2 | K10: =Tabelle2[[#This Row],[propertyID]] -> 8 | L10: 0 | M10: Aeration rate O2 extern | O10: 1 | P10: =Tabelle2[[#This Row],[propertyID]] -> 8 | Q10: 0 | R10: Aeration rate O2 extern | S10: Setpoint | U10: 0 | W10: 0
A11: 9 | B11: 1 | C11: FnN2w | D11: F_{nN2w} | E11: l/min | F11: lmin^{-1} | G11: editfield | H11: 9 | I11: =TEXT(Tabelle2[[#This Row],[category]],"00")&TEXT(Tabelle2[[#This Row],[internal_order]],"00") -> 0109 | J11: 2 | K11: =Tabelle2[[#This Row],[propertyID]] -> 9 | L11: 0 | M11: Aeration rate N2 extern | O11: 1 | P11: =Tabelle2[[#This Row],[propertyID]] -> 9 | Q11: 0 | R11: Aeration rate N2 extern | S11: Setpoint | U11: 0 | W11: 0
A12: 10 | B12: 1 | C12: FnCO2w | D12: F_{nCO2w} | E12: l/min | F12: lmin^{-1} | G12: editfield | H12: 10 | I12: =TEXT(Tabelle2[[#This Row],[category]],"00")&TEXT(Tabelle2[[#This Row],[internal_order]],"00") -> 0110 | J12: 2 | K12: =Tabelle2[[#This Row],[propertyID]] -> 10 | L12: 0 | M12: Aeration rate CO2 extern | O12: 1 | P12: =Tabelle2[[#This Row],[propertyID]] -> 10 | Q12: 0 | R12: Aeration rate CO2 extern | S12: Setpoint | U12: 0 | W12: 0
A13: 11 | B13: 1 | C13: deltapGw | D13: \Deltap_{Gw} | E13: bar | F13: bar | G13: editfield | H13: 11 | I13: =TEXT(Tabelle2[[#This Row],[category]],"00")&TEXT(Tabelle2[[#This Row],[internal_order]],"00") -> 0111 | J13: 2 | K13: =Tabelle2[[#This Row],[propertyID]] -> 11 | L13: 0.5 | M13: Pressure setpoint | O13: 1 | P13: =Tabelle2[[#This Row],[propertyID]] -> 11 | Q13: 0.5 | R13: Pressure setpoint | S13: Setpoint | U13: -1 | W13: -10 | X13: 10
A14: 12 | B14: 1 | C14: FHrelw | D14: F_{Hrelw} | E14: % | F14: % | G14: editfield | H14: 12 | I14: =TEXT(Tabelle2[[#This Row],[category]],"00")&TEXT(Tabelle2[[#This Row],[internal_order]],"00") -> 0112 | J14: 2 | K14: =Tabelle2[[#This Row],[propertyID]] -> 12 | L14: 20 | M14: Harvest rate | O14: 1 | P14: =Tabelle2[[#This Row],[propertyID]] -> 12 | Q14: 20 | R14: Harvest rate | S14: Setpoint | U14: 0 | W14: 0 | X14: 100
A15: 13 | B15: 1 | C15: cS1Lw | D15: c_{S1Lw} | E15: g/l | F15: gl^{-1} | G15: editfield | H15: 13 | I15: =TEXT(Tabelle2[[#This Row],[category]],"00")&TEXT(Tabelle2[[#This Row],[internal_order]],"00") -> 0113 | J15: 2 | K15: =Tabelle2[[#This Row],[propertyID]] -> 13 | L15: 5 | M15: Substrate concentration setpoint for reservoir 1 | O15: 1 | P15: =Tabelle2[[#This Row],[propertyID]] -> 13 | Q15: 0.5 | R15: Substrate concentration setpoint for reservoir 1 | U15: 0 | W15: 0
A16: 14 | B16: 1 | C16: cS2Lw | D16: c_{S2Lw} | E16: g/l | F16: gl^{-1} | G16: editfield | H16: 14 | I16: =TEXT(Tabelle2[[#This Row],[category]],"00")&TEXT(Tabelle2[[#This Row],[internal_order]],"00") -> 0114 | J16: 2 | K16: =Tabelle2[[#This Row],[propertyID]] -> 14 | L16: 2 | M16: Substrate concentration setpoint for reservoir 2 | P16: =Tabelle2[[#This Row],[propertyID]] -> 14 | U16: 0 | W16: 0
A17: 15 | B17: 1 | C17: cS3Lw | D17: c_{S3Lw} | E17: g/l | F17: gl^{-1} | G17: editfield | H17: 15 | I17: =TEXT(Tabelle2[[#This Row],[category]],"00")&TEXT(Tabelle2[[#This Row],[internal_order]],"00") -> 0115 | K17: =Tabelle2[[#This Row],[propertyID]] -> 15 | P17: =Tabelle2[[#This Row],[propertyID]] -> 15 | U17: 0 | W17: 0
A18: 16 | B18: 1 | C18: FR1w | D18: F_{R1w} | E18: l/h | F18: lh^{-1} | G18: editfield | H18: 16 | I18: =TEXT(Tabelle2[[#This Row],[category]],"00")&TEXT(Tabelle2[[#This Row],[internal_order]],"00") -> 0116 | J18: 2 | K18: =Tabelle2[[#This Row],[propertyID]] -> 16 | L18: 0.155 | M18: Pump rate setpoint for reservoir 1 | O18: 1 | P18: =Tabelle2[[#This Row],[propertyID]] -> 16 | Q18: 0.1 | R18: Pump rate setpoint for reservoir 1 | U18: 0 | W18: 0
A19: 17 | B19: 1 | C19: FR2w | D19: F_{R2w} | E19: l/h | F19: lh^{-1} | G19: editfield | H19: 17 | I19: =TEXT(Tabelle2[[#This Row],[category]],"00")&TEXT(Tabelle2[[#This Row],[internal_order]],"00") -> 0117 | J19: 2 | K19: =Tabelle2[[#This Row],[propertyID]] -> 17 | L19: 0.05 | M19: Pump rate setpoint for reservoir 2 | P19: =Tabelle2[[#This Row],[propertyID]] -> 17 | U19: 0 | W19: 0
A20: 18 | B20: 1 | C20: FR3w | D20: F_{R3w} | E20: l/h | F20: lh^{-1} | G20: editfield | H20: 18 | I20: =TEXT(Tabelle2[[#This Row],[category]],"00")&TEXT(Tabelle2[[#This Row],[internal_order]],"00") -> 0118 | K20: =Tabelle2[[#This Row],[propertyID]] -> 18 | P20: =Tabelle2[[#This Row],[propertyID]] -> 18 | U20: 0 | W20: 0
A21: 19 | B21: 2 | C21: cXL0 | D21: c_{XL0} | E21: g/l | F21: gl^{-1} | G21: editfield | H21: 1 | I21: =TEXT(Tabelle2[[#This Row],[category]],"00")&TEXT(Tabelle2[[#This Row],[internal_order]],"00") -> 0201 | J21: 2 | K21: =Tabelle2[[#This Row],[propertyID]] -> 19 | L21: 3 | M21: Initial cell concentration t = 0 h | O21: 1 | P21: =Tabelle2[[#This Row],[propertyID]] -> 19 | Q21: 3 | R21: Initial cell concentration t = 0 h | S21: Initial values | W21: 0
A22: 20 | B22: 2 | C22: pO20 | D22: pO_{20} | E22: % | F22: % | G22: editfield | H22: 2 | I22: =TEXT(Tabelle2[[#This Row],[category]],"00")&TEXT(Tabelle2[[#This Row],[internal_order]],"00") -> 0202 | J22: 2 | K22: =Tabelle2[[#This Row],[propertyID]] -> 20 | L22: 100 | M22: Partial pressure of dissolved oxygen at t = 0 h | O22: 1 | P22: =Tabelle2[[#This Row],[propertyID]] -> 20 | Q22: 100 | R22: Partial pressure of dissolved oxygen at t = 0 h | S22: Initial values | W22: 0
A23: 21 | B23: 2 | C23: pH0 | D23: pH_{0} | E23: - | F23: - | G23: editfield | H23: 3 | I23: =TEXT(Tabelle2[[#This Row],[category]],"00")&TEXT(Tabelle2[[#This Row],[internal_order]],"00") -> 0203 | J23: 2 | K23: =Tabelle2[[#This Row],[propertyID]] -> 21 | L23: 5 | M23: Initial pH at t = 0 h | O23: 1 | P23: =Tabelle2[[#This Row],[propertyID]] -> 21 | Q23: 7.5 | R23: Initial pH at t = 0 h | S23: Initial values | W23: 0
A24: 22 | B24: 2 | C24: VL0 | D24: V_{L0} | E24: l | F24: l | G24: editfield | H24: 4 | I24: =TEXT(Tabelle2[[#This Row],[category]],"00")&TEXT(Tabelle2[[#This Row],[internal_order]],"00") -> 0204 | J24: 2 | K24: =Tabelle2[[#This Row],[propertyID]] -> 22 | L24: 5 | M24: Initial volumme in reactor | O24: 1 | P24: =Tabelle2[[#This Row],[propertyID]] -> 22 | Q24: 10 | R24: Initial volumme in reactor | S24: Initial values | W24: 0
A25: 23 | B25: 2 | C25: thetaL0 | D25: \vartheta_{L0} | E25: °C | F25: °C | G25: editfield | H25: 5 | I25: =TEXT(Tabelle2[[#This Row],[category]],"00")&TEXT(Tabelle2[[#This Row],[internal_order]],"00") -> 0205 | J25: 2 | K25: =Tabelle2[[#This Row],[propertyID]] -> 23 | L25: 30 | M25: Initial temperature in liquid phase at t = 0 h | O25: 1 | P25: =Tabelle2[[#This Row],[propertyID]] -> 23 | Q25: 32 | R25: Initial temperature in liquid phase at t = 0 h | S25: Initial values | W25: 0
A26: 24 | B26: 2 | C26: thetaD0 | D26: \vartheta_{D0} | E26: °C | F26: °C | G26: editfield | H26: 6 | I26: =TEXT(Tabelle2[[#This Row],[category]],"00")&TEXT(Tabelle2[[#This Row],[internal_order]],"00") -> 0206 | J26: 2 | K26: =Tabelle2[[#This Row],[propertyID]] -> 24 | L26: 30 | M26: Initial temperature in double jacket at t = 0 h | O26: 1 | P26: =Tabelle2[[#This Row],[propertyID]] -> 24 | Q26: 32 | R26: Initial temperature in double jacket at t = 0 h | S26: Initial values | W26: 0
A27: 25 | B27: 2 | C27: cS1L0 | D27: c_{S1L0} | E27: g/l | F27: gl^{-1} | G27: editfield | H27: 7 | I27: =TEXT(Tabelle2[[#This Row],[category]],"00")&TEXT(Tabelle2[[#This Row],[internal_order]],"00") -> 0207 | J27: 2 | K27: =Tabelle2[[#This Row],[propertyID]] -> 25 | L27: 25 | M27: Initial glucose concentration t = 0 h | N27: Yuma | O27: 1 | P27: =Tabelle2[[#This Row],[propertyID]] -> 25 | Q27: 5 | R27: Initial glucose concentration t = 0 h | S27: Initial values | W27: 0
A28: 26 | B28: 2 | C28: cS2L0 | D28: c_{S2L0} | E28: g/l | F28: gl^{-1} | G28: editfield | H28: 8 | I28: =TEXT(Tabelle2[[#This Row],[category]],"00")&TEXT(Tabelle2[[#This Row],[internal_order]],"00") -> 0208 | J28: 2 | K28: =Tabelle2[[#This Row],[propertyID]] -> 26 | L28: 0 | M28: Initial glycerine concentration t = 0 h | N28: Yuma | O28: 1 | P28: =Tabelle2[[#This Row],[propertyID]] -> 26 | Q28: 0 | R28: Initial glycerine concentration t = 0 h | S28: Initial values | W28: 0
A29: 27 | B29: 2 | C29: cS3L0 | D29: c_{S3L0} | E29: g/l | F29: gl^{-1} | G29: editfield | H29: 9 | I29: =TEXT(Tabelle2[[#This Row],[category]],"00")&TEXT(Tabelle2[[#This Row],[internal_order]],"00") -> 0209 | J29: 2 | K29: =Tabelle2[[#This Row],[propertyID]] -> 27 | L29: 0 | M29: Initial acetate concentration t = 0 h | N29: Yuma | O29: 1 | P29: =Tabelle2[[#This Row],[propertyID]] -> 27 | Q29: 0 | R29: Initial acetate concentration t = 0 h | S29: Initial values | W29: 0
A30: 28 | B30: 2 | C30: cP1L0 | D30: c_{P1L0} | E30: g/l | F30: gl^{-1} | G30: editfield | H30: 10 | I30: =TEXT(Tabelle2[[#This Row],[category]],"00")&TEXT(Tabelle2[[#This Row],[internal_order]],"00") -> 0210 | J30: 2 | K30: =Tabelle2[[#This Row],[propertyID]] -> 28 | L30: 0 | M30: Product concentration in liquid at t = 0 h | O30: 1 | P30: =Tabelle2[[#This Row],[propertyID]] -> 28 | Q30: 0 | R30: Product concentration in liquid at t = 0 h | W30: 0
A31: 29 | B31: 2 | C31: cP1X0 | D31: c_{P1X0} | E31: g/l | F31: gl^{-1} | G31: editfield | H31: 11 | I31: =TEXT(Tabelle2[[#This Row],[category]],"00")&TEXT(Tabelle2[[#This Row],[internal_order]],"00") -> 0211 | J31: 2 | K31: =Tabelle2[[#This Row],[propertyID]] -> 29 | L31: 0 | M31: Product concentration in cells at t = 0 h | O31: 1 | P31: =Tabelle2[[#This Row],[propertyID]] -> 29 | Q31: 0 | R31: Product concentration in cells at t = 0 h | W31: 0
A32: 30 | B32: 2 | C32: cOL0 | D32: c_{OL0} | E32: g/l | F32: gl^{-1} | G32: editfield | H32: 12 | I32: =TEXT(Tabelle2[[#This Row],[category]],"00")&TEXT(Tabelle2[[#This Row],[internal_order]],"00") -> 0212 | J32: 2 | K32: =Tabelle2[[#This Row],[propertyID]] -> 30 | L32: 0.014735071 | M32: O2-concentration in liquid phase at t = 0 h | N32: delete soon | O32: 1 | P32: =Tabelle2[[#This Row],[propertyID]] -> 30 | Q32: 0.014735071 | R32: O2-concentration in liquid phase at t = 0 h | S32: Initial values | W32: 0
A33: 31 | B33: 3 | C33: pGcal | D33: p_{Gcal} | E33: n/m^2 | F33: nm^{-2} | G33: editfield | H33: 1 | I33: =TEXT(Tabelle2[[#This Row],[category]],"00")&TEXT(Tabelle2[[#This Row],[internal_order]],"00") -> 0301 | J33: 2 | K33: =Tabelle2[[#This Row],[propertyID]] -> 31 | L33: 150000 | M33: Pressure at calibration | O33: 1 | P33: =Tabelle2[[#This Row],[propertyID]] -> 31 | Q33: 150000 | R33: Pressure at calibration | S33: Calibration | W33: 0
A34: 32 | B34: 3 | C34: xOGcal | D34: x_{OGcal} | E34: - | F34: - | G34: editfield | H34: 2 | I34: =TEXT(Tabelle2[[#This Row],[category]],"00")&TEXT(Tabelle2[[#This Row],[internal_order]],"00") -> 0302 | J34: 2 | K34: =Tabelle2[[#This Row],[propertyID]] -> 32 | L34: 0.2094 | M34: Molar concentration of oxygen at calibration | O34: 1 | P34: =Tabelle2[[#This Row],[propertyID]] -> 32 | Q34: 0.2094 | R34: Molar concentration of oxygen at calibration | S34: Calibration | W34: 0
A35: 33 | B35: 3 | C35: xCGcal | D35: x_{CGcal} | E35: - | F35: - | G35: editfield | H35: 3 | I35: =TEXT(Tabelle2[[#This Row],[category]],"00")&TEXT(Tabelle2[[#This Row],[internal_order]],"00") -> 0303 | J35: 2 | K35: =Tabelle2[[#This Row],[propertyID]] -> 33 | L35: 0.004 | M35: Molar concentration of carbon dioxide at calibration | O35: 1 | P35: =Tabelle2[[#This Row],[propertyID]] -> 33 | Q35: 0.004 | R35: Molar concentration of carbon dioxide at calibration | S35: Calibration | W35: 0
A36: 34 | B36: 4 | C36: cS1R1 | D36: c_{S1R1} | E36: g/l | F36: gl^{-1} | G36: editfield | H36: 1 | I36: =TEXT(Tabelle2[[#This Row],[category]],"00")&TEXT(Tabelle2[[#This Row],[internal_order]],"00") -> 0401 | J36: 2 | K36: =Tabelle2[[#This Row],[propertyID]] -> 34 | L36: 150 | M36: Gylcerin concentration in reservoir 1 | N36: Yuma | O36: 1 | P36: =Tabelle2[[#This Row],[propertyID]] -> 34 | Q36: 200 | R36: Glucose concentration in reservoir | S36: Substrate reservoir | W36: 0
A37: 35 | B37: 4 | C37: cS2R1 | D37: c_{S2R1} | E37: g/l | F37: gl^{-1} | G37: editfield | H37: 2 | I37: =TEXT(Tabelle2[[#This Row],[category]],"00")&TEXT(Tabelle2[[#This Row],[internal_order]],"00") -> 0402 | J37: 2 | K37: =Tabelle2[[#This Row],[propertyID]] -> 35 | L37: 0 | M37: Methanol concentration in reservoir1 | N37: Yuma | O37: 1 | P37: =Tabelle2[[#This Row],[propertyID]] -> 35 | Q37: 0 | R37: Gylcerin concentration in reservoir | S37: Substrate reservoir | W37: 0
A38: 36 | B38: 4 | C38: cS3R1 | D38: c_{S3R1} | E38: g/l | F38: gl^{-1} | G38: editfield | H38: 3 | I38: =TEXT(Tabelle2[[#This Row],[category]],"00")&TEXT(Tabelle2[[#This Row],[internal_order]],"00") -> 0403 | K38: =Tabelle2[[#This Row],[propertyID]] -> 36 | O38: 1 | P38: =Tabelle2[[#This Row],[propertyID]] -> 36 | Q38: 0 | R38: Methanol concentration in reservoir | S38: Substrate reservoir | W38: 0
A39: 37 | B39: 4 | C39: cXR1 | D39: c_{XR1} | E39: g/l | F39: gl^{-1} | G39: editfield | H39: 4 | I39: =TEXT(Tabelle2[[#This Row],[category]],"00")&TEXT(Tabelle2[[#This Row],[internal_order]],"00") -> 0404 | J39: 2 | K39: =Tabelle2[[#This Row],[propertyID]] -> 37 | L39: 0 | M39: Concentration of cells in glycerol reservoir | O39: 1 | P39: =Tabelle2[[#This Row],[propertyID]] -> 37 | Q39: 0 | R39: Concentration of cells in glucose reservoir | S39: Substrate reservoir | W39: 0
A40: 38 | B40: 4 | C40: VR10 | D40: V_{R10} | E40: l | F40: l | G40: editfield | H40: 5 | I40: =TEXT(Tabelle2[[#This Row],[category]],"00")&TEXT(Tabelle2[[#This Row],[internal_order]],"00") -> 0405 | J40: 2 | K40: =Tabelle2[[#This Row],[propertyID]] -> 38 | L40: 3 | M40: Glycerol reservoir volume | O40: 1 | P40: =Tabelle2[[#This Row],[propertyID]] -> 38 | Q40: 5 | R40: Glucose reservoir volume | S40: Substrate reservoir | W40: 0
...

Sheet Modes
A1: modesID | B1: propertyID | C1: index | D1: mode
A2: 1 | B2: 92 | C2: 0 | D2: Manual | E2: Mode_feed | F2: Feed_{Mode}
A3: 2 | B3: 92 | C3: 1 | D3: Auto
A4: 3 | B4: 93 | C4: 0 | D4: Manual | E4: Mode_harvest | F4: harvest(LW)_{Mode}
A5: 4 | B5: 93 | C5: 1 | D5: Auto
A6: 5 | B6: 94 | C6: 0 | D6: Manual | E6: Mode_pH | F6: pH_{Mode}
A7: 6 | B7: 94 | C7: 1 | D7: pO2-Agitation
A8: 7 | B8: 94 | C8: 2 | D8: pO2-Aeration | E8: Mode_pO2 | F8: pO_2_{Mode}
A9: 8 | B9: 94 | C9: 3 | D9: pO2-Gasmix
A10: 9 | B10: 94 | C10: 4 | D10: pO2-Feed
A11: 10 | B11: 95 | C11: 0 | D11: Manual
A12: 11 | B12: 95 | C12: 1 | D12: Harvest
A13: 12 | B13: 96 | C13: 0 | D13: Manual | E13: Mode_temp | F13: temp_{Mode}
A14: 13 | B14: 96 | C14: 1 | D14: Feed Control

Sheet Assisting properties
A1: property
A2: ApH
A3: BpH
A4: cCL
A5: cCLmax
A6: cCLmax0
A7: CD
A8: cH2O
A9: CHmax
A10: cOL100
A11: cOLmax
A12: CpH
... A56: qP1pXscript

Sheet all variables
A1: variableID | B1: name | C1: shorttex | D1: longtex | E1: unit | F1: tex_unit | G1: description | H1: variableID3 | I1: selected_variable | J1: limit_type | K1: ymin | L1: ymax | M1: decimalID | N1: colorID | O1: linestyleID | P1: organismID | Q1: variableID2 | R1: visible | S1: upload_rate | T1: Initial_assignment | U1: organismID2 | V1: variableID23 | W1: visible4 | X1: upload_rate5 | Y1: Initial_assignment7
A2: 1 | B2: cXL | C2: c_{XL} | D2: c_{XL} | E2: g/l | F2: gl^{-1} | H2: =Tabelle3[[#This Row],[variableID]] -> 1 | I2: 1 | J2: 1 | K2: 0 | L2: 100 | M2: 1 | N2: 8 | O2: 1 | P2: 1 | Q2: =Tabelle3[[#This Row],[variableID]] -> 1 | R2: 1 | S2: cyclic | T2: app.p.cXL0 | U2: 2 | V2: =Tabelle3[[#This Row],[variableID]] -> 1 | W2: 1 | X2: cyclic | Y2: app.p.cXL0
A3: 2 | B3: cS1L | C3: c_{S1L} | D3: c_{S1L} | E3: g/l | F3: gl^{-1} | H3: =Tabelle3[[#This Row],[variableID]] -> 2 | I3: 1 | J3: 1 | K3: 0 | L3: 5 | M3: 1 | N3: 15 | O3: 1 | P3: 1 | Q3: =Tabelle3[[#This Row],[variableID]] -> 2 | R3: 1 | S3: cyclic | T3: app.p.cS1L0 | U3: 2 | V3: =Tabelle3[[#This Row],[variableID]] -> 2 | W3: 1 | X3: cyclic | Y3: app.p.cS1L0
A4: 3 | B4: cS2L | C4: c_{S2L} | D4: c_{S2L} | E4: g/l | F4: gl^{-1} | H4: =Tabelle3[[#This Row],[variableID]] -> 3 | I4: 0 | J4: 1 | K4: 0 | L4: 10 | M4: 2 | N4: 19 | O4: 1 | P4: 1 | Q4: =Tabelle3[[#This Row],[variableID]] -> 3 | R4: 1 | S4: cyclic | T4: app.p.cS2L0 | U4: 2 | V4: =Tabelle3[[#This Row],[variableID]] -> 3 | W4: 1 | X4: cyclic | Y4: app.p.cS2L0
A5: 4 | B5: cS3L | C5: c_{S3L} | D5: c_{S3L} | E5: g/l | F5: gl^{-1} | H5: =Tabelle3[[#This Row],[variableID]] -> 4 | I5: 0 | J5: 1 | K5: 0 | L5: 0.001 | M5: 4 | N5: 9 | O5: 1 | P5: 1 | Q5: =Tabelle3[[#This Row],[variableID]] -> 4 | R5: 1 | S5: cyclic | T5: app.p.cS3L0 | U5: 2 | V5: =Tabelle3[[#This Row],[variableID]] -> 4 | W5: 1 | X5: never | Y5: app.p.cS3L0
A6: 5 | B6: qXpX | C6: μ | D6: μ | E6: 1/h | F6: h^{-1} | H6: =Tabelle3[[#This Row],[variableID]] -> 5 | I6: 1 | J6: 1 | K6: 0 | L6: 10 | M6: 4 | N6: 18 | O6: 1 | P6: 1 | Q6: =Tabelle3[[#This Row],[variableID]] -> 5 | R6: 1 | S6: cyclic | T6: 0 | U6: 2 | V6: =Tabelle3[[#This Row],[variableID]] -> 5 | W6: 1 | X6: cyclic | Y6: 0
A7: 6 | B7: cP1X | C7: c_{P1X} | D7: c_{P1X} | E7: g/l | F7: gl^{-1} | H7: =Tabelle3[[#This Row],[variableID]] -> 6 | I7: 0 | J7: 1 | K7: 0 | L7: 10 | M7: 3 | N7: 6 | O7: 1 | P7: 1 | Q7: =Tabelle3[[#This Row],[variableID]] -> 6 | R7: 0 | S7: cyclic | T7: app.p.cP1X0 | U7: 2 | V7: =Tabelle3[[#This Row],[variableID]] -> 6 | W7: 0 | X7: cyclic | Y7: app.p.cP1X0
A8: 7 | B8: cP1L | C8: c_{P1L} | D8: c_{P1L} | E8: g/l | F8: gl^{-1} | H8: =Tabelle3[[#This Row],[variableID]] -> 7 | I8: 0 | J8: 1 | K8: 0 | L8: 10 | M8: 3 | N8: 6 | O8: 1 | P8: 1 | Q8: =Tabelle3[[#This Row],[variableID]] -> 7 | R8: 0 | S8: cyclic | T8: app.p.cP1L0 | U8: 2 | V8: =Tabelle3[[#This Row],[variableID]] -> 7 | W8: 0 | X8: cyclic | Y8: app.p.cP1L0
A9: 8 | B9: pO2 | C9: pO_{2} | D9: pO_{2} | E9: % | F9: % | H9: =Tabelle3[[#This Row],[variableID]] -> 8 | I9: 1 | J9: 0 | K9: 0 | L9: 100 | M9: 1 | N9: 6 | O9: 1 | P9: 1 | Q9: =Tabelle3[[#This Row],[variableID]] -> 8 | R9: 1 | S9: cyclic | T9: app.p.pO20 | U9: 2 | V9: =Tabelle3[[#This Row],[variableID]] -> 8 | W9: 1 | X9: cyclic | Y9: app.p.pO20
A10: 9 | B10: NSt | C10: N_{St} | D10: N_{St} | E10: rpm | F10: rpm | H10: =Tabelle3[[#This Row],[variableID]] -> 9 | I10: 1 | J10: 1 | K10: 0 | L10: 2000 | M10: 1 | N10: 1 | O10: 1 | P10: 1 | Q10: =Tabelle3[[#This Row],[variableID]] -> 9 | R10: 1 | S10: cyclic | T10: app.p.NStw | U10: 2 | V10: =Tabelle3[[#This Row],[variableID]] -> 9 | W10: 1 | X10: cyclic | Y10: app.p.NStw
A11: 10 | B11: FnG | C11: F_{nG} | D11: F_{nG} | E11: l/min | F11: lmin^{-1} | H11: =Tabelle3[[#This Row],[variableID]] -> 10 | I11: 0 | J11: 1 | K11: 0 | L11: 10 | M11: 1 | N11: 7 | O11: 1 | P11: 1 | Q11: =Tabelle3[[#This Row],[variableID]] -> 10 | R11: 1 | S11: cyclic | T11: app.v.FnAIR(1)+app.v.FnO2(1)+app.v.FnN2(1)+app.v.FnCO2(1) | U11: 2 | V11: =Tabelle3[[#This Row],[variableID]] -> 10 | W11: 1 | X11: cyclic | Y11: app.v.FnAIR(1)+app.v.FnO2(1)+app.v.FnN2(1)+app.v.FnCO2(1)
A12: 11 | B12: FnAIR | C12: F_{nAIR} | D12: F_{nAIR} | E12: l/min | F12: lmin^{-1} | H12: =Tabelle3[[#This Row],[variableID]] -> 11 | I12: 0 | J12: 1 | K12: 0 | L12: 10 | M12: 4 | N12: 6 | O12: 1 | P12: 1 | Q12: =Tabelle3[[#This Row],[variableID]] -> 11 | R12: 1 | S12: cyclic | T12: app.p.FnAIRw | U12: 2 | V12: =Tabelle3[[#This Row],[variableID]] -> 11 | W12: 1 | X12: cyclic | Y12: app.p.FnAIRw
A13: 12 | B13: FnO2 | C13: F_{nO_2} | D13: F_{nO_2} | E13: l/min | F13: lmin^{-1} | H13: =Tabelle3[[#This Row],[variableID]] -> 12 | I13: 0 | J13: 1 | K13: 0 | L13: 10 | M13: 4 | N13: 1 | O13: 1 | P13: 1 | Q13: =Tabelle3[[#This Row],[variableID]] -> 12 | R13: 1 | S13: cyclic | T13: app.p.FnO2w | U13: 2 | V13: =Tabelle3[[#This Row],[variableID]] -> 12 | W13: 1 | X13: cyclic | Y13: app.p.FnO2w
A14: 13 | B14: FnN2 | C14: F_{nN_2} | D14: F_{nN_2} | E14: l/min | F14: lmin^{-1} | H14: =Tabelle3[[#This Row],[variableID]] -> 13 | I14: 0 | J14: 1 | K14: 0 | L14: 10 | M14: 1 | N14: 5 | O14: 1 | P14: 1 | Q14: =Tabelle3[[#This Row],[variableID]] -> 13 | R14: 1 | S14: cyclic | T14: app.p.FnN2w | U14: 2 | V14: =Tabelle3[[#This Row],[variableID]] -> 13 | W14: 1 | X14: cyclic | Y14: app.p.FnN2w
A15: 14 | B15: FnCO2 | C15: F_{nCO_2} | D15: F_{nCO_2} | E15: l/min | F15: lmin^{-1} | H15: =Tabelle3[[#This Row],[variableID]] -> 14 | I15: 0 | J15: 1 | K15: 0 | L15: 10 | M15: 1 | N15: 2 | O15: 1 | P15: 1 | Q15: =Tabelle3[[#This Row],[variableID]] -> 14 | R15: 1 | S15: cyclic | T15: app.p.FnCO2w | U15: 2 | V15: =Tabelle3[[#This Row],[variableID]] -> 14 | W15: 1 | X15: cyclic | Y15: app.p.FnCO2w
A16: 15 | B16: pHL | C16: pH_{L} | D16: pH_{L} | E16: - | F16: - | H16: =Tabelle3[[#This Row],[variableID]] -> 15 | I16: 0 | J16: 0 | K16: 5 | L16: 8 | M16: 2 | N16: 3 | O16: 1 | P16: 1 | Q16: =Tabelle3[[#This Row],[variableID]] -> 15 | R16: 1 | S16: cyclic | T16: app.p.pH0 | U16: 2 | V16: =Tabelle3[[#This Row],[variableID]] -> 15 | W16: 1 | X16: cyclic | Y16: app.p.pH0
A17: 16 | B17: thetaL | C17: \vartheta_{L} | D17: \vartheta_{L} | E17: °C | F17: °C | H17: =Tabelle3[[#This Row],[variableID]] -> 16 | I17: 1 | J17: 1 | K17: 30 | L17: 40 | M17: 1 | N17: 4 | O17: 1 | P17: 1 | Q17: =Tabelle3[[#This Row],[variableID]] -> 16 | R17: 1 | S17: cyclic | T17: app.p.thetaL0 | U17: 2 | V17: =Tabelle3[[#This Row],[variableID]] -> 16 | W17: 1 | X17: cyclic | Y17: app.p.thetaL0
A18: 17 | B18: pG | C18: p_G | D18: p_G | E18: pa | F18: pa | H18: =Tabelle3[[#This Row],[variableID]] -> 17 | I18: 0 | J18: 0 | K18: 0 | L18: 20000 | M18: 1 | N18: 6 | O18: 1 | P18: 1 | Q18: =Tabelle3[[#This Row],[variableID]] -> 17 | R18: 1 | S18: cyclic | T18: app.p.pGcal+app.p.deltapGw*10^5 | U18: 2 | V18: =Tabelle3[[#This Row],[variableID]] -> 17 | W18: 1 | X18: cyclic | Y18: app.p.pGcal+app.p.deltapGw*10^5
... A23: 23 | B23: cOL | C23: c_{OL} | D23: c_{OL} | E23: g/l | F23: gl^{-1} | H23: =Tabelle3[[#This Row],[variableID]] -> 23 | I23: 0 | J23: 1 | K23: 0 | L23: 0.1 | M23: 1 | N23: 1 | O23: 1 | P23: 1 | Q23: =Tabelle3[[#This Row],[variableID]] -> 23 | R23: 1 | S23: cyclic | T23: (app.p.pO20/100)*app.p.cOL100 | U23: 2 | V23: =Tabelle3[[#This Row],[variableID]] -> 23 | W23: 1 | X23: cyclic | Y23: (app.p.pO20/100)*app.p.cOL100
A24: 24 | B24: RQ | C24: RQ | D24: RQ | E24: mol/mol | F24: molmol^{-1} | H24: =Tabelle3[[#This Row],[variableID]] -> 24 | I24: 0 | J24: 1 | K24: 0 | L24: 2 | M24: 1 | N24: 6 | O24: 1 | P24: 1 | Q24: =Tabelle3[[#This Row],[variableID]] -> 24 | R24: 1 | S24: cyclic | T24: 0.1 | U24: 2 | V24: =Tabelle3[[#This Row],[variableID]] -> 24 | W24: 1 | X24: cyclic | Y24: 0.1
A25: 25 | B25: QO2max | C25: Q_{O2max} | D25: Q_{O2max} | E25: g/(lh) | F25: g(lh)^{-1} | H25: =Tabelle3[[#This Row],[variableID]] -> 25 | I25: 0 | J25: 0 | K25: 0 | L25: 1 | M25: 1 | N25: 6 | O25: 1 | P25: 1 | Q25: =Tabelle3[[#This Row],[variableID]] -> 25 | R25: 1 | S25: end | T25: app.v.FnG(1)*60*app.p.MO2/(app.v.VL(1)*app.p.VnM) | U25: 2 | V25: =Tabelle3[[#This Row],[variableID]] -> 25 | W25: 1 | X25: end | Y25: app.v.FnG(1)*60*app.p.MO2/(app.v.VL(1)*app.p.VnM)
A26: 26 | B26: QCO2max | C26: Q_{CO2max} | D26: Q_{CO2max} | E26: g/(lh) | F26: g(lh)^{-1} | H26: =Tabelle3[[#This Row],[variableID]] -> 26 | I26: 0 | J26: 1 | K26: 0 | L26: 1 | M26: 4 | N26: 2 | O26: 1 | P26: 1 | Q26: =Tabelle3[[#This Row],[variableID]] -> 26 | R26: 1 | S26: end | T26: app.v.QO2max(1)*app.p.MCO2/app.p.MO2 | U26: 2 | V26: =Tabelle3[[#This Row],[variableID]] -> 26 | W26: 1 | X26: end | Y26: app.v.QO2max(1)*app.p.MCO2/app.p.MO2
A27: 27 | B27: OTR | C27: OTR | D27: OTR | E27: g/(lh) | F27: g(lh)^{-1} | H27: =Tabelle3[[#This Row],[variableID]] -> 27 | I27: 0 | J27: 1 | K27: 0 | L27: 1 | M27: 4 | N27: 13 | O27: 1 | P27: 1 | Q27: =Tabelle3[[#This Row],[variableID]] -> 27 | R27: 1 | S27: cyclic | T27: app.v.OTRmax(end)*(app.p.xOAIR-app.v.cOL(end)/app.p.cOLmax) | U27: 2 | V27: =Tabelle3[[#This Row],[variableID]] -> 27 | W27: 1 | X27: cyclic | Y27: app.v.OTRmax(end)*(app.p.xOAIR-app.v.cOL(end)/app.p.cOLmax)
A28: 28 | B28: CTR | C28: CTR | D28: CTR | E28: g/(lh) | F28: g(lh)^{-1} | H28: =Tabelle3[[#This Row],[variableID]] -> 28 | I28: 0 | J28: 1 | K28: 0 | L28: 1 | M28: 4 | N28: 6 | O28: 1 | P28: 1 | Q28: =Tabelle3[[#This Row],[variableID]] -> 28 | R28: 1 | S28: cyclic | T28: 0 | U28: 2 | V28: =Tabelle3[[#This Row],[variableID]] -> 28 | W28: 1 | X28: cyclic | Y28: 0
A29: 29 | B29: OUR | C29: OUR | D29: OUR | E29: g/(lh) | F29: g(lh)^{-1} | H29: =Tabelle3[[#This Row],[variableID]] -> 29 | I29: 0 | J29: 1 | K29: 0 | L29: 1 | M29: 4 | N29: 13 | O29: 1 | P29: 1 | Q29: =Tabelle3[[#This Row],[variableID]] -> 29 | R29: 1 | S29: cyclic | T29: 0 | U29: 2 | V29: =Tabelle3[[#This Row],[variableID]] -> 29 | W29: 1 | X29: cyclic | Y29: 0
A30: 30 | B30: kLa | C30: k_La | D30: k_La | E30: 1/h | F30: h^{-1} | H30: =Tabelle3[[#This Row],[variableID]] -> 30 | I30: 0 | J30: 1 | K30: 0 | L30: 1000 | M30: 4 | N30: 5 | O30: 1 | P30: 1 | Q30: =Tabelle3[[#This Row],[variableID]] -> 30 | R30: 1 | S30: cyclic | T30: app.p.kLamin+app.p.kLamax*((app.p.FnGw/app.p.FnGmax)^app.p.beta)*((app.p.NStw/app.p.NStmax)^(3*app.p.alpha))/((app.p.VL0/app.p.VLmin)^app.p.alpha) | U30: 2 | V30: =Tabelle3[[#This Row],[variableID]] -> 30 | W30: 1 | X30: cyclic | Y30: app.p.kLamin+app.p.kLamax*((app.p.FnGw/app.p.FnGmax)^app.p.beta)*((app.p.NStw/app.p.NStmax)^(3*app.p.alpha))/((app.p.VL0/app.p.VLmin)^app.p.alpha)
A31: 31 | B31: OURm | C31: OURm | D31: OURm | E31: g/(lh) | F31: g(lh)^{-1} | H31: =Tabelle3[[#This Row],[variableID]] -> 31 | I31: 0 | J31: 1 | K31: 0 | L31: 1 | M31: 4 | N31: 18 | O31: 1 | P31: 1 | Q31: =Tabelle3[[#This Row],[variableID]] -> 31 | R31: 0 | S31: end | T31: 0 | U31: 2 | V31: =Tabelle3[[#This Row],[variableID]] -> 31 | W31: 0 | X31: end | Y31: 0
A32: 32 | B32: FH | C32: F_{H} | D32: F_{H} | E32: l/h | F32: lh^{-1} | H32: =Tabelle3[[#This Row],[variableID]] -> 32 | I32: 0 | J32: 1 | K32: 0 | L32: 1 | M32: 1 | N32: 1 | O32: 1 | P32: 1 | Q32: =Tabelle3[[#This Row],[variableID]] -> 32 | R32: 0 | S32: cyclic | T32: app.p.FHrelw/100*app.p.Fhmax | U32: 2 | V32: =Tabelle3[[#This Row],[variableID]] -> 32 | W32: 0 | X32: cyclic | Y32: app.p.FHrelw/100*app.p.Fhmax
A33: 33 | B33: CAlLtot | C33: C_{AlLtot} | D33: C_{AlLtot} | E33: mol/l | F33: moll^{-1} | H33: =Tabelle3[[#This Row],[variableID]] -> 33 | I33: 0 | J33: 1 | K33: 0 | L33: 10 | M33: 1 | N33: 1 | O33: 1 | P33: 1 | Q33: =Tabelle3[[#This Row],[variableID]] -> 33 | R33: 0 | S33: cyclic | T33: app.p.CAlLtot0 | U33: 2 | V33: =Tabelle3[[#This Row],[variableID]] -> 33 | W33: 0 | X33: cyclic | Y33: app.p.CAlLtot0
A34: 34 | B34: Vacid | C34: V_{acid} | D34: added acid | E34: l | F34: l | H34: =Tabelle3[[#This Row],[variableID]] -> 34 | I34: 0 | J34: 1 | K34: 0 | L34: 10 | M34: 1 | N34: 1 | O34: 1 | P34: 1 | Q34: =Tabelle3[[#This Row],[variableID]] -> 34 | R34: 1 | S34: cyclic | T34: 0 | U34: 2 | V34: =Tabelle3[[#This Row],[variableID]] -> 34 | W34: 1 | X34: cyclic | Y34: 0
A35: 35 | B35: Vbase | C35: V_{base} | D35: added base | E35: l | F35: l | H35: =Tabelle3[[#This Row],[variableID]] -> 35 | I35: 0 | J35: 1 | K35: 0 | L35: 10 | M35: 1 | N35: 1 | O35: 1 | P35: 1 | Q35: =Tabelle3[[#This Row],[variableID]] -> 35 | R35: 1 | S35: cyclic | T35: 0 | U35: 2 | V35: =Tabelle3[[#This Row],[variableID]] -> 35 | W35: 1 | X35: cyclic | Y35: 0
A36: 36 | B36: AAF | C36: A_{AF} | D36: added antifoam | E36: l | F36: l | H36: =Tabelle3[[#This Row],[variableID]] -> 36 | I36: 0 | J36: 1 | K36: 0 | L36: 10 | M36: 1 | N36: 1 | O36: 1 | P36: 1 | Q36: =Tabelle3[[#This Row],[variableID]] -> 36 | R36: 1 | S36: cyclic | T36: 0 | U36: 2 | V36: =Tabelle3[[#This Row],[variableID]] -> 36 | W36: 1 | X36: cyclic | Y36: 0
A37: 37 | B37: VL | C37: V_{L} | D37: V_{L} | E37: l | F37: l | H37: =Tabelle3[[#This Row],[variableID]] -> 37 | I37: 0 | J37: 1 | K37: 0 | L37: 10 | M37: 1 | N37: 1 | O37: 1 | P37: 1 | Q37: =Tabelle3[[#This Row],[variableID]] -> 37 | R37: 1 | S37: cyclic | T37: app.p.VL0 | U37: 2 | V37: =Tabelle3[[#This Row],[variableID]] -> 37 | W37: 1 | X37: cyclic | Y37: app.p.VL0
A38: 38 | B38: VT1 | C38: V_{T1} | D38: V_{T1} | E38: l | F38: l | H38: =Tabelle3[[#This Row],[variableID]] -> 38 | I38: 0 | J38: 1 | K38: 0 | L38: 10 | M38: 1 | N38: 1 | O38: 1 | P38: 1 | Q38: =Tabelle3[[#This Row],[variableID]] -> 38 | R38: 1 | S38: cyclic | T38: app.p.VT10 | U38: 2 | V38: 37 | W38: 1 | X38: cyclic | Y38: app.p.VT10
A39: 39 | B39: VT2 | C39: V_{T2} | D39: V_{T2} | E39: l | F39: l | H39: =Tabelle3[[#This Row],[variableID]] -> 39 | I39: 0 | J39: 1 | K39: 0 | L39: 10 | M39: 1 | N39: 1 | O39: 1 | P39: 1 | Q39: =Tabelle3[[#This Row],[variableID]] -> 39 | R39: 1 | S39: cyclic | T39: app.p.VT20 | U39: 2 | V39: 38 | W39: 1 | X39: cyclic | Y39: app.p.VT20
A40: 40 | B40: FT1 | C40: F_{T1} | D40: F_{T1} | E40: l/h | F40: lh^{-1} | G40: Pump rate acid | H40: =Tabelle3[[#This Row],[variableID]] -> 40 | I40: 0 | J40: 1 | K40: 0 | L40: 10 | M40: 1 | N40: 1 | O40: 1 | P40: 1 | Q40: =Tabelle3[[#This Row],[variableID]] -> 40 | R40: 1 | S40: cyclic | T40: app.p.FT10 | U40: 2 | V40: =Tabelle3[[#This Row],[variableID]] -> 40 | W40: 1 | X40: cyclic | Y40: app.p.FT10
A41: 41 | B41: FT2 | C41: F_{T2} | D41: F_{T2} | E41: l/h | F41: lh^{-1} | G41: Pump rate base | H41: =Tabelle3[[#This Row],[variableID]] -> 41 | I41: 0 | J41: 1 | K41: 0 | L41: 10 | M41: 1 | N41: 1 | O41: 1 | P41: 1 | Q41: =Tabelle3[[#This Row],[variableID]] -> 41 | R41: 1 | S41: cyclic | T41: app.p.FT20 | U41: 2 | V41: =Tabelle3[[#This Row],[variableID]] -> 41 | W41: 1 | X41: cyclic | Y41: app.p.FT20
A42: 42 | B42: CAcLtot | C42: C_{AcLtot} | D42: C_{AcLtot} | E42: mol/l | F42: moll^{-1} | H42: =Tabelle3[[#This Row],[variableID]] -> 42 | I42: 0 | J42: 1 | K42: 0 | L42: 10 | M42: 1 | N42: 1 | O42: 1 | P42: 1 | Q42: =Tabelle3[[#This Row],[variableID]] -> 42 | R42: 0 | S42: cyclic | T42: app.p.CAcLtot0 | U42: 2 | V42: =Tabelle3[[#This Row],[variableID]] -> 42 | W42: 0 | X42: cyclic | Y42: app.p.CAcLtot0
A43: 43 | B43: pHLm | C43: pH_{Lm} | D43: pH_{Lm} | E43: - | F43: - | H43: =Tabelle3[[#This Row],[variableID]] -> 43 | I43: 0 | J43: 1 | K43: 3 | L43: 8 | M43: 1 | N43: 1 | O43: 1 | P43: 1 | Q43: =Tabelle3[[#This Row],[variableID]] -> 43 | R43: 1 | S43: cyclic | T43: app.p.pH0 | U43: 2 | V43: =Tabelle3[[#This Row],[variableID]] -> 43 | W43: 1 | X43: cyclic | Y43: app.p.pH0
A44: 44 | B44: thetaLm | C44: \vartheta_{Lm} | D44: \vartheta_{Lm} | E44: °C | F44: °C | H44: =Tabelle3[[#This Row],[variableID]] -> 44 | I44: 0 | J44: 1 | K44: 30 | L44: 40 | M44: 1 | N44: 1 | O44: 1 | P44: 1 | Q44: =Tabelle3[[#This Row],[variableID]] -> 44 | R44: 1 | S44: cyclic | T44: app.p.thetaL0 | U44: 2 | V44: =Tabelle3[[#This Row],[variableID]] -> 44 | W44: 1 | X44: cyclic | Y44: app.p.thetaL0
...

Sheet CategoryTab
A1: categoryID | B1: name | C1: section | D1: reading_rate
A2: 1 | B2: Setpoint | C2: Parameters | D2: cyclic
A3: 2 | B3: Initial value | C3: Parameters | D3: once
A4: 3 | B4: Calibration | C4: Parameters | D4: once
A5: 4 | B5: Substrate reservoir | C5: Parameters | D5: once
A6: 5 | B6: Feed control | C6: Parameters | D6: cyclic
A7: 6 | B7: pH control | C7: Parameters | D7: once
A8: 7 | B8: Modes | C8: Parameters | D8: cyclic
A9: 8 | B9: Flags | C9: Parameters | D9: cyclic
A10: 9 | B10: Controller gain | C10: Parameters | D10: cyclic
A11: 10 | B11: General | C11: General | D11: once
A12: 11 | B12: Cell growth | C12: Organism | D12: once
A13: 12 | B13: Growth temperature | C13: Organism | D13: once
... A20: 19 | B20: Temperature control | C20: Bioreactor | D20: once

Sheet Bacillus properties
A1: propertyID | B1: category | C1: name | D1: tex | E1: value | F1: unit | G1: description | H1: Categories
A2: 1 | B2: 1 | C2: deltapGw | D2: \Deltap_{Gw} | E2: 0.5 | F2: bar | G2: Pressure setpoint | H2: Setpoint
A3: 2 | B3: 1 | C3: FHrelw | D3: F_{Hrelw} | E3: 20 | F3: % | G3: Harvest rate | H3: Setpoint
A4: 3 | B4: 1 | C4: FnAIRw | D4: F_{nAIRw} | E4: 7.5 | F4: l/min | G4: Aeration rate AIR extern | H4: Setpoint
A5: 4 | B5: 1 | C5: FnCO2w | D5: F_{nCO2w} | E5: 0 | F5: l/min | G5: Aeration rate CO2 extern | H5: Setpoint
A6: 5 | B6: 1 | C6: FnGw | D6: F_{nGw} | E6: 6 | F6: l/min | G6: Value of chosen aeration rate | H6: Setpoint
A7: 6 | B7: 1 | C7: FnN2w | D7: F_{nN2w} | E7: 0 | F7: l/min | G7: Aeration rate N2 extern | H7: Setpoint
A8: 7 | B8: 1 | C8: FnO2w | D8: F_{nO2w} | E8: 0 | F8: l/min | G8: Aeration rate O2 extern | H8: Setpoint
A9: 8 | B9: 1 | C9: FRw | D9: F_{Rw} | E9: 0 | F9: l/h | G9: Value of chosen constant feed rate | H9: Setpoint
A10: 9 | B10: 1 | C10: LWw | D10: L_{Ww} | E10: 14 | F10: kg | G10: Liquid weight setpoint | H10: Setpoint
A11: 10 | B11: 1 | C11: NStw | D11: N_{Stw} | E11: 400 | F11: 1/min | G11: Setpoint for agitation speed | H11: Setpoint
A12: 11 | B12: 1 | C12: pHw | D12: pH_{w} | E12: 6.7 | F12: - | G12: Value of pH Setpoint | H12: Setpoint
A13: 12 | B13: 1 | C13: pO2w | D13: pO_{2w} | E13: 20 | F13: % | G13: Value of pO2 setpoint | H13: Setpoint
... A56: 57 | B56: 5 | C56: VT20 | D56: V_{T20} | E56: 1 | F56: l | G56: Base reservoir volume at t = 0 h | H56: pH control
A57: 58 | B57: 6 | C57: f_motor | D57: motor | E57: 1 | G57: Signal for stirrer to be turned on/off | H57: Flags
A58: 59 | B58: 6 | C58: f_aeration | D58: aeration | E58: 1 | G58: Signal for aeration to be turned on/off | H58: Flags
A59: 60 | B59: 6 | C59: f_air | D59: air | E59: 0 | G59: Signal for aeration with AIR | H59: Flags
A60: 61 | B60: 6 | C60: f_N2 | D60: N_2 | E60: 0 | G60: Signal for aeration with N2 | H60: Flags
A61: 62 | B61: 6 | C61: f_O2 | D61: O_2 | E61: 0 | G61: Signal for aeration with O2 | H61: Flags
A62: 63 | B62: 6 | C62: f_CO2 | D62: CO_2 | E62: 0 | G62: Signal for aeration with CO2 | H62: Flags
A63: 64 | B63: 6 | C63: f_feed | D63: feed | E63: 0 | G63: Signal for feed to be turned on/off | H63: Flags
A64: 65 | B64: 6 | C64: f_harvest | D64: harvest | E64: 0 | G64: Signal for harvest to be turned on/off | H64: Flags
A65: 66 | B65: 6 | C65: f_antifoam | D65: antifoam | E65: 0 | G65: Signal for antifoam addition | H65: Flags
A66: 67 | B66: 6 | C66: f_alkali | D66: alkali | E66: 0 | G66: Signal for alkali addition | H66: Flags
A67: 68 | B67: 6 | C67: f_acid | D67: acid | E67: 0 | G67: Signal for acid addition | H67: Flags
A68: 69 | B68: 6 | C68: f_cooling | D68: cooling | E68: 0 | G68: Signal for cooling | H68: Flags
... A104: 105 | B104: 7 | C104: KD_LW | D104: KD_{LW} | E104: 1 | G104: Gain of D part of liquid weight controller | H104: Controller gain
A105: 106 | B105: 8 | C105: xOAIR | D105: x_{OAIR} | E105: 0.2094 | F105: - | G105: Molar concentration of oxygen in AIR | H105: General
A106: 107 | B106: 8 | C106: xCAIR | D106: x_{CAIR} | E106: 0.0003 | F106: - | G106: Molar concentration of carbondioxide in AIR | H106: General
A107: 108 | B107: 8 | C107: HnO2 | D107: H_{nO2} | E107: 1448000 | F107: N*m/kg | G107: O2 Henry constant under normal conditions | H107: General
A108: 109 | B108: 8 | C108: HO20 | D108: H_{O20} | E108: 1440000 | F108: N*m/kg | G108: O2 Henry constant | H108: General
A109: 110 | B109: 8 | C109: HnCO2 | D109: H_{nCO2} | E109: 30010 | F109: N*m/kg | G109: CO2 Henry constant under normal conditions | H109: General
A110: 111 | B110: 8 | C110: HCO20 | D110: H_{CO20} | E110: 30010 | F110: N*m/kg | G110: CO2 Henry constant | H110: General
A111: 112 | B111: 8 | C111: VnM | D111: V_{nM} | E111: 22.412 | F111: l/mol | G111: Gas volume under normal conditions | H111: General
A112: 113 | B112: 8 | C112: MO2 | D112: M_{O2} | E112: 32 | F112: g/mol | G112: Molar mass of O2 | H112: General
A113: 114 | B113: 8 | C113: MCO2 | D113: M_{CO2} | E113: 44 | F113: g/mol | G113: Molar mass of CO2 | H113: General
A114: 115 | B114: 8 | C114: TnG | D114: T_{nG} | E114: 273.15 | F114: K | G114: Gas temperature under normal conditions | H114: General
A115: 116 | B115: 8 | C115: pnG | D115: p_{nG} | E115: 101330 | F115: N/m^2 | G115: Gas pressure under normal conditions | H115: General
A116: 117 | B116: 8 | C116: R | D116: R | E116: 8314 | F116: N*m/(kmol*K) | G116: Gas constant | H116: General
... A237: 238 | B237: 16 | C237: deltat | D237: \Deltat | E237: 1.8 | F237: s | G237: Calculation interval | H237: Settings
...

Sheet Process Tables
A1: Process_statusTab | D1: Process_typeTab | K1: Process_operatorTab | O1: Process_conditionTab
A2: Process_statusID | B2: status | D2: Process_typeID | E2: type | K2: Process_operatorID | L2: condition | M2: operator | O2: Process_conditionID | P2: Process_sectionID | Q2: Process_variableID | R2: Process_operatorID | S2: value
A3: 1 | B3: completed | D3: 1 | E3: Costum | K3: 1 | L3: ≥ | M3: >= | O3: 1 | P3: 1 | Q3: t | R3: 5 | S3: 0
A4: 2 | B4: active | D4: 2 | E4: Batch | K4: 2 | L4: ≤ | M4: <= | O4: 2 | P4: 2 | Q4: pO2 | R4: 1 | S4: 50
A5: 3 | B5: upcoming | D5: 3 | E5: Fed-Batch | K5: 3 | L5: > | M5: > | O5: 3 | P5: 2 | Q5: t | R5: 5 | S5: 5
D6: 4 | E6: Pulse-Feed | K6: 4 | L6: < | M6: <
K7: 5 | L7: = | M7: =
A14: Process_phaseTab | D14: status | E14: type | G14: start_variable | H14: start_condition | I14: start_value | K14: Process_variableTab
A15: Process_phaseID | B15: projectID | C15: order | D15: Process_statusID | E15: Process_typeTab | F15: name | G15: Process_conditionID | K15: Process_variableID | L15: variableID
A16: 1 | B16: 1 | C16: 1 | D16: 1 | E16: 2 | F16: Batch | G16: 1 | K16: 1 | L16: 1
A17: 2 | B17: 1 | C17: 2 | D17: 2 | E17: 3 | F17: Fed-Batch 1 | G17: 2 | K17: 2 | L17: 2
A18: 3 | B18: 1 | C18: 3 | D18: 3 | E18: 4 | F18: Pulse-Feed | K18: 3 | L18: 3
A19: 4 | B19: 1 | C19: 4 | D19: 3 | E19: 3 | F19: Fed-Batch 2 | K19: 4 | L19: 4
K20: 5 | L20: 5
K21: 6 | L21: 6
K22: 7 | L22: 7
K23: 8 | L23: 8
K24: 9 | L24: 9
K25: 10 | L25: 10
K26: 11 | L26: 11
K27: 12 | L27: 12
K28: 13 | L28: 13
K29: 14 | L29: 14
K30: 15 | L30: 15
K31: 16 | L31: 16
... K41: 26 | L41: 37

Sheet Plot Variables
A1: profileID | B1: variableID | C1: name | D1: shorttex | E1: longtex | F1: unit | G1: tex_unit | H1: description | I1: displayed | J1: upload_rate | K1: Column1 | L1: limit_type | M1: ymin | N1: ymax | O1: decimalID | P1: colorID | Q1: linestyleID | R1: selected
A2: 1 | B2: 1 | C2: cXL | D2: c_{XL} | E2: c_{XL} | F2: g/l | G2: gl^{-1} | I2: 1 | J2: cyclic | L2: 1 | M2: 0 | N2: 100 | O2: 1 | P2: 8 | Q2: 1 | R2: 0
A3: 1 | B3: 2 | C3: cS1L | D3: c_{S1L} | E3: c_{S1L} | F3: g/l | G3: gl^{-1} | I3: 1 | J3: cyclic | L3: 1 | M3: 0 | N3: 5 | O3: 1 | P3: 15 | Q3: 1 | R3: 0
A4: 1 | B4: 3 | C4: cS2L | D4: c_{S2L} | E4: c_{S2L} | F4: g/l | G4: gl^{-1} | I4: 1 | J4: cyclic | L4: 1 | M4: 0 | N4: 10 | O4: 2 | P4: 19 | Q4: 1 | R4: 0
A5: 1 | B5: 4 | C5: cS3L | D5: c_{S3L} | E5: c_{S3L} | F5: g/l | G5: gl^{-1} | I5: 1 | J5: cyclic | L5: 1 | M5: 0 | N5: 0.001 | O5: 4 | P5: 9 | Q5: 1 | R5: 0
A6: 1 | B6: 5 | C6: qXpX | D6: μ | E6: μ | F6: 1/h | G6: h^{-1} | I6: 1 | J6: cyclic | L6: 1 | M6: 0 | N6: 10 | O6: 4 | P6: 18 | Q6: 1 | R6: 0
A7: 1 | B7: 6 | C7: CPLtot | D7: C_{PLtot} | E7: C_{PLtot} | F7: mol/l | G7: mol/l | I7: 0 | J7: cyclic | L7: 1 | M7: 0 | N7: 10 | O7: 1 | P7: 1 | Q7: 1 | R7: 0
A8: 1 | B8: 7 | C8: pO2 | D8: pO_{2} | E8: pO_{2} | F8: % | G8: % | I8: 1 | J8: cyclic | L8: 0 | M8: 0 | N8: 100 | O8: 1 | P8: 6 | Q8: 1 | R8: 0
A9: 1 | B9: 8 | C9: NSt | D9: N_{St} | E9: N_{St} | F9: rpm | G9: rpm | I9: 1 | J9: cyclic | L9: 1 | M9: 0 | N9: 2000 | O9: 4 | P9: 5 | Q9: 1 | R9: 0
A10: 1 | B10: 9 | C10: FnG | D10: F_{nG} | E10: F_{nG} | F10: l/min | G10: lmin^{-1} | I10: 1 | J10: cyclic | L10: 1 | M10: 0 | N10: 10 | O10: 4 | P10: 7 | Q10: 1 | R10: 0
A11: 1 | B11: 10 | C11: FnAIR | D11: F_{nAIR} | E11: F_{nAIR} | F11: l/min | G11: lmin^{-1} | I11: 0 | J11: cyclic | L11: 1 | M11: 0 | N11: 10 | O11: 4 | P11: 6 | Q11: 1 | R11: 1
